<sdf version='1.3'>
  <world name='default'>
    <light name='sun' type='directional'>
      <cast_shadows>1</cast_shadows>
      <pose>0.000000 0.000000 10.000000 0.000000 0.000000 0.000000</pose>
      <diffuse>0.800000 0.800000 0.800000 1.000000</diffuse>
      <specular>0.100000 0.100000 0.100000 1.000000</specular>
      <attenuation>
        <range>1000.000000</range>
        <constant>0.900000</constant>
        <linear>0.010000</linear>
        <quadratic>0.001000</quadratic>
      </attenuation>
      <direction>-0.500000 0.500000 -1.000000</direction>
    </light>
    <model name='ground_plane'>
      <static>1</static>
      <link name='link'>
        <collision name='collision'>
          <geometry>
            <plane>
              <normal>0.000000 0.000000 1.000000</normal>
              <size>100.000000 100.000000</size>
            </plane>
          </geometry>
          <surface>
            <friction>
              <ode>
                <mu>100.000000</mu>
                <mu2>50.000000</mu2>
              </ode>
            </friction>
            <bounce/>
            <contact>
              <ode/>
            </contact>
          </surface>
        </collision>
        <visual name='visual'>
          <cast_shadows>0</cast_shadows>
          <geometry>
            <plane>
              <normal>0.000000 0.000000 1.000000</normal>
              <size>100.000000 100.000000</size>
            </plane>
          </geometry>
          <material>
            <script>
              <uri>file://media/materials/scripts/gazebo.material</uri>
              <name>Gazebo/Grey</name>
            </script>
          </material>
        </visual>
        <velocity_decay>
          <linear>0.000000</linear>
          <angular>0.000000</angular>
        </velocity_decay>
        <self_collide>0</self_collide>
        <kinematic>0</kinematic>
        <gravity>1</gravity>
      </link>
    </model>
    <physics type='ode'>
      <update_rate>1000.000000</update_rate>
      <gravity>0.000000 0.000000 -9.800000</gravity>
    </physics>
    <scene>
      <ambient>0.200000 0.200000 0.200000 1.000000</ambient>
      <background>0.700000 0.700000 0.700000 1.000000</background>
      <shadows>1</shadows>
    </scene>
    <model name='teste'>
      <link name='Wall_10'>
        <collision name='Wall_10_Collision'>
          <geometry>
            <box>
              <size>22.440900 0.200000 2.500000</size>
            </box>
          </geometry>
          <pose>0.000000 0.000000 1.250000 0.000000 0.000000 0.000000</pose>
          <surface>
            <bounce/>
            <friction>
              <ode/>
            </friction>
            <contact>
              <ode/>
            </contact>
          </surface>
        </collision>
        <visual name='Wall_10_Visual'>
          <pose>0.000000 0.000000 1.250000 0.000000 0.000000 0.000000</pose>
          <geometry>
            <box>
              <size>22.440900 0.200000 2.500000</size>
            </box>
          </geometry>
          <material>
            <script>
              <uri>file://media/materials/scripts/gazebo.material</uri>
              <name>Gazebo/Grey</name>
            </script>
          </material>
        </visual>
        <velocity_decay>
          <linear>0.000000</linear>
          <angular>0.000000</angular>
        </velocity_decay>
        <pose>0.702739 9.650490 0.000000 0.000000 0.000000 0.000000</pose>
        <self_collide>0</self_collide>
        <kinematic>0</kinematic>
        <gravity>1</gravity>
      </link>
      <link name='Wall_11'>
        <collision name='Wall_11_Collision'>
          <geometry>
            <box>
              <size>19.745600 0.200000 2.500000</size>
            </box>
          </geometry>
          <pose>0.000000 0.000000 1.250000 0.000000 0.000000 0.000000</pose>
          <surface>
            <bounce/>
            <friction>
              <ode/>
            </friction>
            <contact>
              <ode/>
            </contact>
          </surface>
        </collision>
        <visual name='Wall_11_Visual'>
          <pose>0.000000 0.000000 1.250000 0.000000 0.000000 0.000000</pose>
          <geometry>
            <box>
              <size>19.745600 0.200000 2.500000</size>
            </box>
          </geometry>
          <material>
            <script>
              <uri>file://media/materials/scripts/gazebo.material</uri>
              <name>Gazebo/Grey</name>
            </script>
          </material>
        </visual>
        <velocity_decay>
          <linear>0.000000</linear>
          <angular>0.000000</angular>
        </velocity_decay>
        <pose>11.823200 -0.122327 0.000000 0.000000 0.000000 -1.570800</pose>
        <self_collide>0</self_collide>
        <kinematic>0</kinematic>
        <gravity>1</gravity>
      </link>
      <link name='Wall_12'>
        <collision name='Wall_12_Collision'>
          <geometry>
            <box>
              <size>22.307100 0.200000 2.500000</size>
            </box>
          </geometry>
          <pose>0.000000 0.000000 1.250000 0.000000 0.000000 0.000000</pose>
          <surface>
            <bounce/>
            <friction>
              <ode/>
            </friction>
            <contact>
              <ode/>
            </contact>
          </surface>
        </collision>
        <visual name='Wall_12_Visual'>
          <pose>0.000000 0.000000 1.250000 0.000000 0.000000 0.000000</pose>
          <geometry>
            <box>
              <size>22.307100 0.200000 2.500000</size>
            </box>
          </geometry>
          <material>
            <script>
              <uri>file://media/materials/scripts/gazebo.material</uri>
              <name>Gazebo/Grey</name>
            </script>
          </material>
        </visual>
        <velocity_decay>
          <linear>0.000000</linear>
          <angular>0.000000</angular>
        </velocity_decay>
        <pose>0.769605 -9.895140 0.000000 0.000000 0.000000 3.141590</pose>
        <self_collide>0</self_collide>
        <kinematic>0</kinematic>
        <gravity>1</gravity>
      </link>
      <link name='Wall_13'>
        <collision name='Wall_13_Collision'>
          <geometry>
            <box>
              <size>19.746100 0.200000 2.500000</size>
            </box>
          </geometry>
          <pose>0.000000 0.000000 1.250000 0.000000 0.000000 0.000000</pose>
          <surface>
            <bounce/>
            <friction>
              <ode/>
            </friction>
            <contact>
              <ode/>
            </contact>
          </surface>
        </collision>
        <visual name='Wall_13_Visual'>
          <pose>0.000000 0.000000 1.250000 0.000000 0.000000 0.000000</pose>
          <geometry>
            <box>
              <size>19.746100 0.200000 2.500000</size>
            </box>
          </geometry>
          <material>
            <script>
              <uri>file://media/materials/scripts/gazebo.material</uri>
              <name>Gazebo/Grey</name>
            </script>
          </material>
        </visual>
        <velocity_decay>
          <linear>0.000000</linear>
          <angular>0.000000</angular>
        </velocity_decay>
        <pose>-10.350800 -0.122327 0.000000 0.000000 0.000000 1.577640</pose>
        <self_collide>0</self_collide>
        <kinematic>0</kinematic>
        <gravity>1</gravity>
      </link>
      <link name='Wall_16'>
        <collision name='Wall_16_Collision'>
          <geometry>
            <box>
              <size>4.033000 0.200000 2.500000</size>
            </box>
          </geometry>
          <pose>0.000000 0.000000 1.250000 0.000000 0.000000 0.000000</pose>
          <surface>
            <bounce/>
            <friction>
              <ode/>
            </friction>
            <contact>
              <ode/>
            </contact>
          </surface>
        </collision>
        <visual name='Wall_16_Visual'>
          <pose>0.000000 0.000000 1.250000 0.000000 0.000000 0.000000</pose>
          <geometry>
            <box>
              <size>4.033000 0.200000 2.500000</size>
            </box>
          </geometry>
          <material>
            <script>
              <uri>file://media/materials/scripts/gazebo.material</uri>
              <name>Gazebo/Grey</name>
            </script>
          </material>
        </visual>
        <velocity_decay>
          <linear>0.000000</linear>
          <angular>0.000000</angular>
        </velocity_decay>
        <pose>-8.333660 -7.343360 0.000000 0.000000 0.000000 0.000000</pose>
        <self_collide>0</self_collide>
        <kinematic>0</kinematic>
        <gravity>1</gravity>
      </link>
      <link name='Wall_18'>
        <collision name='Wall_18_Collision'>
          <geometry>
            <box>
              <size>6.304410 0.200000 2.500000</size>
            </box>
          </geometry>
          <pose>0.000000 0.000000 1.250000 0.000000 0.000000 0.000000</pose>
          <surface>
            <bounce/>
            <friction>
              <ode/>
            </friction>
            <contact>
              <ode/>
            </contact>
          </surface>
        </collision>
        <visual name='Wall_18_Visual'>
          <pose>0.000000 0.000000 1.250000 0.000000 0.000000 0.000000</pose>
          <geometry>
            <box>
              <size>6.304410 0.200000 2.500000</size>
            </box>
          </geometry>
          <material>
            <script>
              <uri>file://media/materials/scripts/gazebo.material</uri>
              <name>Gazebo/Grey</name>
            </script>
          </material>
        </visual>
        <velocity_decay>
          <linear>0.000000</linear>
          <angular>0.000000</angular>
        </velocity_decay>
        <pose>0.751975 -7.201400 0.000000 0.000000 0.000000 0.000000</pose>
        <self_collide>0</self_collide>
        <kinematic>0</kinematic>
        <gravity>1</gravity>
      </link>
      <link name='Wall_20'>
        <collision name='Wall_20_Collision'>
          <geometry>
            <box>
              <size>2.400430 0.200000 2.500000</size>
            </box>
          </geometry>
          <pose>0.000000 0.000000 1.250000 0.000000 0.000000 0.000000</pose>
          <surface>
            <bounce/>
            <friction>
              <ode/>
            </friction>
            <contact>
              <ode/>
            </contact>
          </surface>
        </collision>
        <visual name='Wall_20_Visual'>
          <pose>0.000000 0.000000 1.250000 0.000000 0.000000 0.000000</pose>
          <geometry>
            <box>
              <size>2.400430 0.200000 2.500000</size>
            </box>
          </geometry>
          <material>
            <script>
              <uri>file://media/materials/scripts/gazebo.material</uri>
              <name>Gazebo/Grey</name>
            </script>
          </material>
        </visual>
        <velocity_decay>
          <linear>0.000000</linear>
          <angular>0.000000</angular>
        </velocity_decay>
        <pose>8.453470 -7.130420 0.000000 0.000000 0.000000 0.000000</pose>
        <self_collide>0</self_collide>
        <kinematic>0</kinematic>
        <gravity>1</gravity>
      </link>
      <link name='Wall_21'>
        <collision name='Wall_21_Collision'>
          <geometry>
            <box>
              <size>4.458890 0.200000 2.500000</size>
            </box>
          </geometry>
          <pose>0.000000 0.000000 1.250000 0.000000 0.000000 0.000000</pose>
          <surface>
            <bounce/>
            <friction>
              <ode/>
            </friction>
            <contact>
              <ode/>
            </contact>
          </surface>
        </collision>
        <visual name='Wall_21_Visual'>
          <pose>0.000000 0.000000 1.250000 0.000000 0.000000 0.000000</pose>
          <geometry>
            <box>
              <size>4.458890 0.200000 2.500000</size>
            </box>
          </geometry>
          <material>
            <script>
              <uri>file://media/materials/scripts/gazebo.material</uri>
              <name>Gazebo/Grey</name>
            </script>
          </material>
        </visual>
        <velocity_decay>
          <linear>0.000000</linear>
          <angular>0.000000</angular>
        </velocity_decay>
        <pose>9.553680 -5.000970 0.000000 0.000000 0.000000 1.570800</pose>
        <self_collide>0</self_collide>
        <kinematic>0</kinematic>
        <gravity>1</gravity>
      </link>
      <link name='Wall_23'>
        <collision name='Wall_23_Collision'>
          <geometry>
            <box>
              <size>4.082100 0.200000 2.500000</size>
            </box>
          </geometry>
          <pose>0.000000 0.000000 1.250000 0.000000 0.000000 0.000000</pose>
          <surface>
            <bounce/>
            <friction>
              <ode/>
            </friction>
            <contact>
              <ode/>
            </contact>
          </surface>
        </collision>
        <visual name='Wall_23_Visual'>
          <pose>0.000000 0.000000 1.250000 0.000000 0.000000 0.000000</pose>
          <geometry>
            <box>
              <size>4.082100 0.200000 2.500000</size>
            </box>
          </geometry>
          <material>
            <script>
              <uri>file://media/materials/scripts/gazebo.material</uri>
              <name>Gazebo/Grey</name>
            </script>
          </material>
        </visual>
        <velocity_decay>
          <linear>0.000000</linear>
          <angular>0.000000</angular>
        </velocity_decay>
        <pose>-2.336370 -5.270570 0.000000 0.000000 0.000000 1.561710</pose>
        <self_collide>0</self_collide>
        <kinematic>0</kinematic>
        <gravity>1</gravity>
      </link>
      <link name='Wall_24'>
        <collision name='Wall_24_Collision'>
          <geometry>
            <box>
              <size>2.740910 0.200000 2.500000</size>
            </box>
          </geometry>
          <pose>0.000000 0.000000 1.250000 0.000000 0.000000 0.000000</pose>
          <surface>
            <bounce/>
            <friction>
              <ode/>
            </friction>
            <contact>
              <ode/>
            </contact>
          </surface>
        </collision>
        <visual name='Wall_24_Visual'>
          <pose>0.000000 0.000000 1.250000 0.000000 0.000000 0.000000</pose>
          <geometry>
            <box>
              <size>2.740910 0.200000 2.500000</size>
            </box>
          </geometry>
          <material>
            <script>
              <uri>file://media/materials/scripts/gazebo.material</uri>
              <name>Gazebo/Grey</name>
            </script>
          </material>
        </visual>
        <velocity_decay>
          <linear>0.000000</linear>
          <angular>0.000000</angular>
        </velocity_decay>
        <pose>-1.048270 -3.329600 0.000000 0.000000 0.000000 0.000000</pose>
        <self_collide>0</self_collide>
        <kinematic>0</kinematic>
        <gravity>1</gravity>
      </link>
      <link name='Wall_26'>
        <collision name='Wall_26_Collision'>
          <geometry>
            <box>
              <size>9.516650 0.200000 2.500000</size>
            </box>
          </geometry>
          <pose>0.000000 0.000000 1.250000 0.000000 0.000000 0.000000</pose>
          <surface>
            <bounce/>
            <friction>
              <ode/>
            </friction>
            <contact>
              <ode/>
            </contact>
          </surface>
        </collision>
        <visual name='Wall_26_Visual'>
          <pose>0.000000 0.000000 1.250000 0.000000 0.000000 0.000000</pose>
          <geometry>
            <box>
              <size>9.516650 0.200000 2.500000</size>
            </box>
          </geometry>
          <material>
            <script>
              <uri>file://media/materials/scripts/gazebo.material</uri>
              <name>Gazebo/Grey</name>
            </script>
          </material>
        </visual>
        <velocity_decay>
          <linear>0.000000</linear>
          <angular>0.000000</angular>
        </velocity_decay>
        <pose>2.269020 -1.494510 0.000000 0.000000 0.000000 0.000000</pose>
        <self_collide>0</self_collide>
        <kinematic>0</kinematic>
        <gravity>1</gravity>
      </link>
      <link name='Wall_27'>
        <collision name='Wall_27_Collision'>
          <geometry>
            <box>
              <size>5.670000 0.200000 2.500000</size>
            </box>
          </geometry>
          <pose>0.000000 0.000000 1.250000 0.000000 0.000000 0.000000</pose>
          <surface>
            <bounce/>
            <friction>
              <ode/>
            </friction>
            <contact>
              <ode/>
            </contact>
          </surface>
        </collision>
        <visual name='Wall_27_Visual'>
          <pose>0.000000 0.000000 1.250000 0.000000 0.000000 0.000000</pose>
          <geometry>
            <box>
              <size>5.670000 0.200000 2.500000</size>
            </box>
          </geometry>
          <material>
            <script>
              <uri>file://media/materials/scripts/gazebo.material</uri>
              <name>Gazebo/Grey</name>
            </script>
          </material>
        </visual>
        <velocity_decay>
          <linear>0.000000</linear>
          <angular>0.000000</angular>
        </velocity_decay>
        <pose>6.927350 1.240490 0.000000 0.000000 0.000000 1.570800</pose>
        <self_collide>0</self_collide>
        <kinematic>0</kinematic>
        <gravity>1</gravity>
      </link>
      <link name='Wall_28'>
        <collision name='Wall_28_Collision'>
          <geometry>
            <box>
              <size>0.210000 0.200000 2.500000</size>
            </box>
          </geometry>
          <pose>0.000000 0.000000 1.250000 0.000000 0.000000 0.000000</pose>
          <surface>
            <bounce/>
            <friction>
              <ode/>
            </friction>
            <contact>
              <ode/>
            </contact>
          </surface>
        </collision>
        <visual name='Wall_28_Visual'>
          <pose>0.000000 0.000000 1.250000 0.000000 0.000000 0.000000</pose>
          <geometry>
            <box>
              <size>0.210000 0.200000 2.500000</size>
            </box>
          </geometry>
          <material>
            <script>
              <uri>file://media/materials/scripts/gazebo.material</uri>
              <name>Gazebo/Grey</name>
            </script>
          </material>
        </visual>
        <velocity_decay>
          <linear>0.000000</linear>
          <angular>0.000000</angular>
        </velocity_decay>
        <pose>6.932350 3.975500 0.000000 0.000000 0.000000 0.000000</pose>
        <self_collide>0</self_collide>
        <kinematic>0</kinematic>
        <gravity>1</gravity>
      </link>
      <link name='Wall_30'>
        <collision name='Wall_30_Collision'>
          <geometry>
            <box>
              <size>3.376130 0.200000 2.500000</size>
            </box>
          </geometry>
          <pose>0.000000 0.000000 1.250000 0.000000 0.000000 0.000000</pose>
          <surface>
            <bounce/>
            <friction>
              <ode/>
            </friction>
            <contact>
              <ode/>
            </contact>
          </surface>
        </collision>
        <visual name='Wall_30_Visual'>
          <pose>0.000000 0.000000 1.250000 0.000000 0.000000 0.000000</pose>
          <geometry>
            <box>
              <size>3.376130 0.200000 2.500000</size>
            </box>
          </geometry>
          <material>
            <script>
              <uri>file://media/materials/scripts/gazebo.material</uri>
              <name>Gazebo/Grey</name>
            </script>
          </material>
        </visual>
        <velocity_decay>
          <linear>0.000000</linear>
          <angular>0.000000</angular>
        </velocity_decay>
        <pose>6.962640 5.492980 0.000000 0.000000 0.000000 1.570800</pose>
        <self_collide>0</self_collide>
        <kinematic>0</kinematic>
        <gravity>1</gravity>
      </link>
      <link name='Wall_32'>
        <collision name='Wall_32_Collision'>
          <geometry>
            <box>
              <size>3.764320 0.200000 2.500000</size>
            </box>
          </geometry>
          <pose>0.000000 0.000000 1.250000 0.000000 0.000000 0.000000</pose>
          <surface>
            <bounce/>
            <friction>
              <ode/>
            </friction>
            <contact>
              <ode/>
            </contact>
          </surface>
        </collision>
        <visual name='Wall_32_Visual'>
          <pose>0.000000 0.000000 1.250000 0.000000 0.000000 0.000000</pose>
          <geometry>
            <box>
              <size>3.764320 0.200000 2.500000</size>
            </box>
          </geometry>
          <material>
            <script>
              <uri>file://media/materials/scripts/gazebo.material</uri>
              <name>Gazebo/Grey</name>
            </script>
          </material>
        </visual>
        <velocity_decay>
          <linear>0.000000</linear>
          <angular>0.000000</angular>
        </velocity_decay>
        <pose>5.180480 3.975500 0.000000 0.000000 0.000000 3.141590</pose>
        <self_collide>0</self_collide>
        <kinematic>0</kinematic>
        <gravity>1</gravity>
      </link>
      <link name='Wall_34'>
        <collision name='Wall_34_Collision'>
          <geometry>
            <box>
              <size>5.564130 0.200000 2.500000</size>
            </box>
          </geometry>
          <pose>0.000000 0.000000 1.250000 0.000000 0.000000 0.000000</pose>
          <surface>
            <bounce/>
            <friction>
              <ode/>
            </friction>
            <contact>
              <ode/>
            </contact>
          </surface>
        </collision>
        <visual name='Wall_34_Visual'>
          <pose>0.000000 0.000000 1.250000 0.000000 0.000000 0.000000</pose>
          <geometry>
            <box>
              <size>5.564130 0.200000 2.500000</size>
            </box>
          </geometry>
          <material>
            <script>
              <uri>file://media/materials/scripts/gazebo.material</uri>
              <name>Gazebo/Grey</name>
            </script>
          </material>
        </visual>
        <velocity_decay>
          <linear>0.000000</linear>
          <angular>0.000000</angular>
        </velocity_decay>
        <pose>-2.389300 1.187560 0.000000 0.000000 0.000000 1.570800</pose>
        <self_collide>0</self_collide>
        <kinematic>0</kinematic>
        <gravity>1</gravity>
      </link>
      <link name='Wall_35'>
        <collision name='Wall_35_Collision'>
          <geometry>
            <box>
              <size>3.199680 0.200000 2.500000</size>
            </box>
          </geometry>
          <pose>0.000000 0.000000 1.250000 0.000000 0.000000 0.000000</pose>
          <surface>
            <bounce/>
            <friction>
              <ode/>
            </friction>
            <contact>
              <ode/>
            </contact>
          </surface>
        </collision>
        <visual name='Wall_35_Visual'>
          <pose>0.000000 0.000000 1.250000 0.000000 0.000000 0.000000</pose>
          <geometry>
            <box>
              <size>3.199680 0.200000 2.500000</size>
            </box>
          </geometry>
          <material>
            <script>
              <uri>file://media/materials/scripts/gazebo.material</uri>
              <name>Gazebo/Grey</name>
            </script>
          </material>
        </visual>
        <velocity_decay>
          <linear>0.000000</linear>
          <angular>0.000000</angular>
        </velocity_decay>
        <pose>-0.889463 3.869630 0.000000 0.000000 0.000000 0.000000</pose>
        <self_collide>0</self_collide>
        <kinematic>0</kinematic>
        <gravity>1</gravity>
      </link>
      <link name='Wall_37'>
        <collision name='Wall_37_Collision'>
          <geometry>
            <box>
              <size>9.551940 0.200000 2.500000</size>
            </box>
          </geometry>
          <pose>0.000000 0.000000 1.250000 0.000000 0.000000 0.000000</pose>
          <surface>
            <bounce/>
            <friction>
              <ode/>
            </friction>
            <contact>
              <ode/>
            </contact>
          </surface>
        </collision>
        <visual name='Wall_37_Visual'>
          <pose>0.000000 0.000000 1.250000 0.000000 0.000000 0.000000</pose>
          <geometry>
            <box>
              <size>9.551940 0.200000 2.500000</size>
            </box>
          </geometry>
          <material>
            <script>
              <uri>file://media/materials/scripts/gazebo.material</uri>
              <name>Gazebo/Grey</name>
            </script>
          </material>
        </visual>
        <velocity_decay>
          <linear>0.000000</linear>
          <angular>0.000000</angular>
        </velocity_decay>
        <pose>2.321960 7.151630 0.000000 0.000000 0.000000 3.141590</pose>
        <self_collide>0</self_collide>
        <kinematic>0</kinematic>
        <gravity>1</gravity>
      </link>
      <link name='Wall_39'>
        <collision name='Wall_39_Collision'>
          <geometry>
            <box>
              <size>5.387680 0.200000 2.500000</size>
            </box>
          </geometry>
          <pose>0.000000 0.000000 1.250000 0.000000 0.000000 0.000000</pose>
          <surface>
            <bounce/>
            <friction>
              <ode/>
            </friction>
            <contact>
              <ode/>
            </contact>
          </surface>
        </collision>
        <visual name='Wall_39_Visual'>
          <pose>0.000000 0.000000 1.250000 0.000000 0.000000 0.000000</pose>
          <geometry>
            <box>
              <size>5.387680 0.200000 2.500000</size>
            </box>
          </geometry>
          <material>
            <script>
              <uri>file://media/materials/scripts/gazebo.material</uri>
              <name>Gazebo/Grey</name>
            </script>
          </material>
        </visual>
        <velocity_decay>
          <linear>0.000000</linear>
          <angular>0.000000</angular>
        </velocity_decay>
        <pose>-4.947850 1.011110 0.000000 0.000000 0.000000 3.141590</pose>
        <self_collide>0</self_collide>
        <kinematic>0</kinematic>
        <gravity>1</gravity>
      </link>
      <link name='Wall_40'>
        <collision name='Wall_40_Collision'>
          <geometry>
            <box>
              <size>3.411420 0.200000 2.500000</size>
            </box>
          </geometry>
          <pose>0.000000 0.000000 1.250000 0.000000 0.000000 0.000000</pose>
          <surface>
            <bounce/>
            <friction>
              <ode/>
            </friction>
            <contact>
              <ode/>
            </contact>
          </surface>
        </collision>
        <visual name='Wall_40_Visual'>
          <pose>0.000000 0.000000 1.250000 0.000000 0.000000 0.000000</pose>
          <geometry>
            <box>
              <size>3.411420 0.200000 2.500000</size>
            </box>
          </geometry>
          <material>
            <script>
              <uri>file://media/materials/scripts/gazebo.material</uri>
              <name>Gazebo/Grey</name>
            </script>
          </material>
        </visual>
        <velocity_decay>
          <linear>0.000000</linear>
          <angular>0.000000</angular>
        </velocity_decay>
        <pose>-7.541690 2.616820 0.000000 0.000000 0.000000 1.570800</pose>
        <self_collide>0</self_collide>
        <kinematic>0</kinematic>
        <gravity>1</gravity>
      </link>
      <static>1</static>
    </model>
    <model name='pioneer3at_0'>
      <pose>-8.000000 -8.590790 0.180000 0.000000 0.000000 0.000000</pose>
      <static>0</static>
      <link name='chassis'>
        <inertial>
          <mass>14.000000</mass>
          <inertia>
            <ixx>0.333800</ixx>
            <ixy>0.000000</ixy>
            <ixz>0.000000</ixz>
            <iyy>0.478300</iyy>
            <iyz>0.000000</iyz>
            <izz>0.333800</izz>
          </inertia>
        </inertial>
        <collision name='collision'>
          <geometry>
            <box>
              <size>0.501000 0.400000 0.190000</size>
            </box>
          </geometry>
          <surface>
            <bounce/>
            <friction>
              <ode/>
            </friction>
            <contact>
              <ode/>
            </contact>
          </surface>
        </collision>
        <visual name='visual'>
          <geometry>
            <mesh>
              <uri>model://pioneer3at/meshes/chassis.dae</uri>
            </mesh>
          </geometry>
        </visual>
        <velocity_decay>
          <linear>0.000000</linear>
          <angular>0.000000</angular>
        </velocity_decay>
        <self_collide>0</self_collide>
        <kinematic>0</kinematic>
        <gravity>1</gravity>
      </link>
      <link name='right_front_wheel'>
        <pose>0.125000 -0.201000 -0.060000 1.570700 0.000000 0.000000</pose>
        <collision name='collision'>
          <geometry>
            <cylinder>
              <radius>0.110000</radius>
              <length>0.075000</length>
            </cylinder>
          </geometry>
          <surface>
            <friction>
              <ode>
                <mu>1.000000</mu>
                <mu2>1.000000</mu2>
                <slip1>0.500000</slip1>
                <slip2>0.000000</slip2>
              </ode>
            </friction>
            <bounce/>
            <contact>
              <ode/>
            </contact>
          </surface>
        </collision>
        <visual name='visual'>
          <geometry>
            <mesh>
              <uri>model://pioneer3at/meshes/wheel.dae</uri>
            </mesh>
          </geometry>
        </visual>
        <velocity_decay>
          <linear>0.000000</linear>
          <angular>0.000000</angular>
        </velocity_decay>
        <self_collide>0</self_collide>
        <inertial>
          <inertia>
            <ixx>1.000000</ixx>
            <ixy>0.000000</ixy>
            <ixz>0.000000</ixz>
            <iyy>1.000000</iyy>
            <iyz>0.000000</iyz>
            <izz>1.000000</izz>
          </inertia>
          <mass>1.000000</mass>
        </inertial>
        <kinematic>0</kinematic>
        <gravity>1</gravity>
      </link>
      <link name='left_front_wheel'>
        <pose>0.125000 0.201000 -0.060000 1.570700 0.000000 0.000000</pose>
        <collision name='collision'>
          <geometry>
            <cylinder>
              <radius>0.110000</radius>
              <length>0.075000</length>
            </cylinder>
          </geometry>
          <surface>
            <friction>
              <ode>
                <mu>1.000000</mu>
                <mu2>1.000000</mu2>
                <slip1>0.500000</slip1>
                <slip2>0.000000</slip2>
              </ode>
            </friction>
            <bounce/>
            <contact>
              <ode/>
            </contact>
          </surface>
        </collision>
        <visual name='visual'>
          <geometry>
            <mesh>
              <uri>model://pioneer3at/meshes/wheel.dae</uri>
            </mesh>
          </geometry>
        </visual>
        <velocity_decay>
          <linear>0.000000</linear>
          <angular>0.000000</angular>
        </velocity_decay>
        <self_collide>0</self_collide>
        <inertial>
          <inertia>
            <ixx>1.000000</ixx>
            <ixy>0.000000</ixy>
            <ixz>0.000000</ixz>
            <iyy>1.000000</iyy>
            <iyz>0.000000</iyz>
            <izz>1.000000</izz>
          </inertia>
          <mass>1.000000</mass>
        </inertial>
        <kinematic>0</kinematic>
        <gravity>1</gravity>
      </link>
      <link name='right_rear_wheel'>
        <pose>-0.125000 -0.201000 -0.060000 1.570700 0.000000 0.000000</pose>
        <collision name='collision'>
          <geometry>
            <cylinder>
              <radius>0.110000</radius>
              <length>0.075000</length>
            </cylinder>
          </geometry>
          <surface>
            <friction>
              <ode>
                <mu>1.000000</mu>
                <mu2>1.000000</mu2>
                <slip1>0.500000</slip1>
                <slip2>0.000000</slip2>
              </ode>
            </friction>
            <bounce/>
            <contact>
              <ode/>
            </contact>
          </surface>
        </collision>
        <visual name='visual'>
          <geometry>
            <mesh>
              <uri>model://pioneer3at/meshes/wheel.dae</uri>
            </mesh>
          </geometry>
        </visual>
        <velocity_decay>
          <linear>0.000000</linear>
          <angular>0.000000</angular>
        </velocity_decay>
        <self_collide>0</self_collide>
        <inertial>
          <inertia>
            <ixx>1.000000</ixx>
            <ixy>0.000000</ixy>
            <ixz>0.000000</ixz>
            <iyy>1.000000</iyy>
            <iyz>0.000000</iyz>
            <izz>1.000000</izz>
          </inertia>
          <mass>1.000000</mass>
        </inertial>
        <kinematic>0</kinematic>
        <gravity>1</gravity>
      </link>
      <link name='left_rear_wheel'>
        <pose>-0.125000 0.201000 -0.060000 1.570700 0.000000 0.000000</pose>
        <collision name='collision'>
          <geometry>
            <cylinder>
              <radius>0.110000</radius>
              <length>0.075000</length>
            </cylinder>
          </geometry>
          <surface>
            <friction>
              <ode>
                <mu>1.000000</mu>
                <mu2>1.000000</mu2>
                <slip1>0.500000</slip1>
                <slip2>0.000000</slip2>
              </ode>
            </friction>
            <bounce/>
            <contact>
              <ode/>
            </contact>
          </surface>
        </collision>
        <visual name='visual'>
          <geometry>
            <mesh>
              <uri>model://pioneer3at/meshes/wheel.dae</uri>
            </mesh>
          </geometry>
        </visual>
        <velocity_decay>
          <linear>0.000000</linear>
          <angular>0.000000</angular>
        </velocity_decay>
        <self_collide>0</self_collide>
        <inertial>
          <inertia>
            <ixx>1.000000</ixx>
            <ixy>0.000000</ixy>
            <ixz>0.000000</ixz>
            <iyy>1.000000</iyy>
            <iyz>0.000000</iyz>
            <izz>1.000000</izz>
          </inertia>
          <mass>1.000000</mass>
        </inertial>
        <kinematic>0</kinematic>
        <gravity>1</gravity>
      </link>
      <joint name='right_front' type='revolute'>
        <pose>0.000000 0.000000 0.000000 0.000000 0.000000 0.000000</pose>
        <child>right_front_wheel</child>
        <parent>chassis</parent>
        <axis>
          <xyz>0.000000 1.000000 0.000000</xyz>
          <limit>
            <lower>-10000000000000000.000000</lower>
            <upper>10000000000000000.000000</upper>
          </limit>
        </axis>
      </joint>
      <joint name='right_rear' type='revolute'>
        <pose>0.000000 0.000000 0.000000 0.000000 0.000000 0.000000</pose>
        <child>right_rear_wheel</child>
        <parent>chassis</parent>
        <axis>
          <xyz>0.000000 1.000000 0.000000</xyz>
          <limit>
            <lower>-10000000000000000.000000</lower>
            <upper>10000000000000000.000000</upper>
          </limit>
        </axis>
      </joint>
      <joint name='left_front' type='revolute'>
        <pose>0.000000 0.000000 0.000000 0.000000 0.000000 0.000000</pose>
        <child>left_front_wheel</child>
        <parent>chassis</parent>
        <axis>
          <xyz>0.000000 1.000000 0.000000</xyz>
          <limit>
            <lower>-10000000000000000.000000</lower>
            <upper>10000000000000000.000000</upper>
          </limit>
        </axis>
      </joint>
      <joint name='left_rear' type='revolute'>
        <pose>0.000000 0.000000 0.000000 0.000000 0.000000 0.000000</pose>
        <child>left_rear_wheel</child>
        <parent>chassis</parent>
        <axis>
          <xyz>0.000000 1.000000 0.000000</xyz>
          <limit>
            <lower>-10000000000000000.000000</lower>
            <upper>10000000000000000.000000</upper>
          </limit>
        </axis>
      </joint>
      <link name='hokuyo::link'>
        <inertial>
          <mass>0.100000</mass>
          <inertia>
            <ixx>1.000000</ixx>
            <ixy>0.000000</ixy>
            <ixz>0.000000</ixz>
            <iyy>1.000000</iyy>
            <iyz>0.000000</iyz>
            <izz>1.000000</izz>
          </inertia>
        </inertial>
        <visual name='visual'>
          <geometry>
            <mesh>
              <uri>model://hokuyo/meshes/hokuyo.dae</uri>
            </mesh>
          </geometry>
        </visual>
        <collision name='collision-base'>
          <pose>0.000000 0.000000 -0.014500 0.000000 0.000000 0.000000</pose>
          <geometry>
            <box>
              <size>0.050000 0.050000 0.041000</size>
            </box>
          </geometry>
          <surface>
            <bounce/>
            <friction>
              <ode/>
            </friction>
            <contact>
              <ode/>
            </contact>
          </surface>
        </collision>
        <collision name='collision-top'>
          <pose>0.000000 0.000000 0.020500 0.000000 0.000000 0.000000</pose>
          <geometry>
            <cylinder>
              <radius>0.021000</radius>
              <length>0.029000</length>
            </cylinder>
          </geometry>
          <surface>
            <bounce/>
            <friction>
              <ode/>
            </friction>
            <contact>
              <ode/>
            </contact>
          </surface>
        </collision>
        <sensor name='laser' type='ray'>
          <pose>0.010000 0.000000 0.017500 0.000000 0.000000 0.000000</pose>
          <ray>
            <scan>
              <horizontal>
                <samples>720</samples>
                <resolution>1.00000</resolution>
                <min_angle>-1.57</min_angle>
                <max_angle>1.57</max_angle>
              </horizontal>
            </scan>
            <range>
              <min>0.080000</min>
              <max>10.000000</max>
              <resolution>0.010000</resolution>
            </range>
          </ray>
          <plugin name='laser' filename='libRayPlugin.so'/>
          <always_on>1</always_on>
          <update_rate>30.000000</update_rate>
          <visualize>1</visualize>
        </sensor>
        <velocity_decay>
          <linear>0.000000</linear>
          <angular>0.000000</angular>
        </velocity_decay>
        <pose>0.200000 0.000000 0.130000 0.000000 0.000000 0.000000</pose>
        <self_collide>0</self_collide>
        <kinematic>0</kinematic>
        <gravity>1</gravity>
      </link>
      <joint name='hokuyo_joint' type='revolute'>
        <child>hokuyo::link</child>
        <parent>chassis</parent>
        <axis>
          <xyz>0.000000 0.000000 1.000000</xyz>
          <limit>
            <upper>0.000000</upper>
            <lower>0.000000</lower>
          </limit>
        </axis>
      </joint>
      <plugin name='SkidSteerDrivePlugin' filename='libSkidSteerDrivePlugin.so'/>
    </model>
    <state world_name='default'>
      <sim_time>0 0</sim_time>
      <real_time>0 0</real_time>
      <wall_time>1384880067 356130009</wall_time>
    </state>
    <gui fullscreen='0'>
      <camera name='user_camera'>
        <pose>17.848300 -6.776330 19.626200 0.000000 0.751643 2.952190</pose>
        <view_controller>orbit</view_controller>
      </camera>
    </gui>
  </world>
</sdf>
